# 第2章　例外処理

## 例外の発生と例外処理

例外発生時点で、``java.lang.ArithmeticException``という例外オブジェクトが投げられる。(変数eに入り、その後出力する)

```java
public class ExceptionExample3 {
    public static void main(String[] args) {
        int a = 4;
        int b = 0;
        try {
            int c = a / b;
            System.out.println("cの値は" + c );
        }
        catch(ArithmeticException e) {
            System.out.println("例外をキャッチしました");
            System.out.println(e);
            return;
            // returnされ処理は終わるが、finallyは実行される
        }
        finally {
            System.out.println("finallyブロックの処理です");
        }
        System.out.println("プログラムを終了します");
    }
}
```

catch文がなければ、メソッドの呼び出し元まで戻ってcatchブロックを検索する

```java
class SimpleClass {
    void doSomething() {
        int array[] = new int[3];
        array[10] = 99;
        System.out.println("doSomethingメソッドを終了します");
    }
}

public class ExceptionExample5 {
    public static void main(String args[]) {
        SimpleClass obj = new SimpleClass();
        try {
            obj.doSomething();
        }
        catch(ArrayIndexOutOfBoundsException e) {
            System.out.println("例外をキャッチしました");
            e.printStackTrace();
        }
    }
}
```

## 例外オブジェクト

``printStackTrace``：Exceptionクラス：例外が発生するまでのスタックトレースを見れる

例外発生時にcatch文に投げられるのは、正確には、例外オブジェクト。例外オブジェクトの種類に応じて処理の内容を切り替えることができる。

```java
public class ExceptionExample6 {
    public static void main(String[] args) {
        int[] scores = new int[5];
        int a = 4;
        int b = (int)(Math.random() * 10);
        System.out.println("b=" + b);
        try {
            int c = a / b;
            System.out.println("cの値は" + c);
            scores[b] = 10;
            System.out.println("処理が正常に行われました");
        }
        // bが0のとき、0で割ることはできない
        catch(ArithmeticException e) {
            System.out.println("ArithmeticException型の例外をキャッチしました");
            System.out.println(e);
        }
        // bが5以上のとき、5以上のインデックスを持つ配列はない
        catch(ArrayIndexOutOfBoundsException e) {
            System.out.println("ArrayIndexOutOfBoundsException型の例外をキャッチしました");
            System.out.println(e);
        }
        System.out.println("プログラムを終了します");
    }
}
```

``Exception e``：catchブロックの引数を、Exception型にすると、すべての例外オブジェクトをキャッチできる

### 例外のクラス階層

Errorクラス：通常はキャッチすべきでない大きなトラブルが発生したときにしようされる

Exceptionクラス：try〜catch文でキャッチできる。例外の可能性がある場合は、原則として書かなければならない

ただし、RuntimeExceptionクラスだけはtry〜catch文を書かなくてもよい。開発者の判断。


## 例外を作成して投げる

例外オブジェクトは自作できる。自作する際は、Exceptionクラスを継承する。コンストラクタは``super()``で呼び出す。

```java
class InvalidAgeException extends Exception {
    InvalidAgeException(String message) {
        super(message);
    }
}

public class MyExceptionExample {
    public static void main(String[] args) {
        int age = -10;
        try {
            if(age < 0) {
                throw new InvalidAgeException("年齢にマイナスの値が指定されました");
            }
            System.out.println("年齢は" + age + "歳です");
        }
        catch(InvalidAgeException e) {
            System.out.println("例外をキャッチしました");
            System.out.println(e);
        }
    }
}
```

### メソッドの外への例外の送出

throw：例外オブジェクトを投げる
throws：例外を投げる可能性があるメソッドの宣言に使用する。(呼び出し元でtry〜catchする)

```java
class InvalidAgeException extends Exception {
   InvalidAgeException(String message) {
       super(message);
   }
}

class Person {
    int age;
    void setAge(int age) throws InvalidAgeException {
        if(age < 0) {
            throw new InvalidAgeException("年齢にマイナスの値が指定されました");
        }
        this.age = age;
    }
}

public class ExceptionExample7 {
    public static void main(String[] args) {
        Person p = new Person();
        try {
            p.setAge(-5);
        }
        catch(InvalidAgeException e){
            System.out.println(e);
        }
    }
}
```